<?xml version="1.0" ?>
<!-- =================================================================================== -->
<!-- |    This document was autogenerated by xacro from mbot.xacro                     | -->
<!-- |    EDITING THIS FILE BY HAND IS NOT RECOMMENDED                                 | -->
<!-- =================================================================================== -->
<robot name="mbot" xmlns:xacro="http://www.ros.org/wiki/xacro">
  <material name="yellow">
    <color rgba="1 0.4 0 1"/>
  </material>
  <material name="black">
    <color rgba="0 0 0 0.95"/>
  </material>
  <material name="gray">
    <color rgba="0.75 0.75 0.75 1"/>
  </material>
  <link name="base_footprint">
    <visual>
      <origin rpy="0 0 0" xyz="0 0 0"/>
      <geometry>
        <box size="0.001 0.001 0.001"/>
      </geometry>
    </visual>
  </link>
  <joint name="base_footprint_joint" type="fixed">
    <origin rpy="0 0 0" xyz="0 0 0.2625"/>
    <parent link="base_link"/>
    <child link="base_footprint"/>
  </joint>
  <link name="base_link">
    <inertial>
      <mass value="2"/>
      <origin xyz="0 0 0.0"/>
      <inertia ixx="0.01" ixy="0.0" ixz="0.0" iyy="0.01" iyz="0.0" izz="0.5"/>
    </inertial>
    <visual>
      <origin rpy="0 0 0" xyz="0 0 0"/>
      <geometry>
        <cylinder length="0.005" radius="0.13"/>
      </geometry>
      <material name="yellow"/>
    </visual>
    <collision>
      <origin rpy="0 0 0" xyz="0 0 0"/>
      <geometry>
        <cylinder length="0.005" radius="0.13"/>
      </geometry>
    </collision>
  </link>
  <joint name="base_left_motor_joint" type="fixed">
    <origin rpy="0 0 0" xyz="-0.055 -0.075 0"/>
    <parent link="base_link"/>
    <child link="left_motor"/>
  </joint>
  <link name="left_motor">
    <visual>
      <origin rpy="1.570795 0 0" xyz="0 0 0"/>
      <geometry>
        <cylinder length="0.08" radius="0.02"/>
      </geometry>
      <material name="gray"/>
    </visual>
  </link>
  <joint name="base_right_motor_joint" type="fixed">
    <origin rpy="0 0 0" xyz="-0.055 0.075 0"/>
    <parent link="base_link"/>
    <child link="right_motor"/>
  </joint>
  <link name="right_motor">
    <visual>
      <origin rpy="1.570795 0 0" xyz="0 0 0"/>
      <geometry>
        <cylinder length="0.08" radius="0.02"/>
      </geometry>
      <material name="gray"/>
    </visual>
  </link>
  <joint name="left_wheel_joint" type="continuous">
    <origin rpy="0 0 0" xyz="0 -0.0485 0"/>
    <parent link="left_motor"/>
    <child link="left_wheel_link"/>
    <axis xyz="0 1 0"/>
  </joint>
  <link name="left_wheel_link">
    <visual>
      <origin rpy="1.570795 0 0" xyz="0 0 0"/>
      <geometry>
        <cylinder length="0.017" radius="0.033"/>
      </geometry>
      <material name="gray"/>
    </visual>
  </link>
  <joint name="right_wheel_joint" type="continuous">
    <origin rpy="0 0 0" xyz="0 0.0485 0"/>
    <parent link="right_motor"/>
    <child link="right_wheel_link"/>
    <axis xyz="0 1 0"/>
  </joint>
  <link name="right_wheel_link">
    <visual>
      <origin rpy="1.570795 0 0" xyz="0 0 0"/>
      <geometry>
        <cylinder length="0.017" radius="0.033"/>
      </geometry>
      <material name="gray"/>
    </visual>
  </link>
  <joint name="front_castor_joint" type="fixed">
    <origin rpy="0 0 0" xyz="-0.1135 0 -0.0165"/>
    <parent link="base_link"/>
    <child link="front_castor_link"/>
    <axis xyz="0 1 0"/>
  </joint>
  <link name="front_castor_link">
    <visual>
      <origin rpy="1.570795 0 0" xyz="0 0 0"/>
      <geometry>
        <sphere radius="0.0165"/>
      </geometry>
      <material name="black"/>
    </visual>
  </link>
</robot>

